<?xml version="1.0" encoding="UTF-8"?>
<!-- Generated by org.testng.reporters.JUnitReportReporter -->
<testsuite hostname="DESKTOP-HSEV31H" failures="0" tests="8" name="TestNGPractice.RetryFailDemo" time="0.030" errors="1" timestamp="2022-09-14T13:15:29 IST" skipped="4">
  <testcase classname="TestNGPractice.RetryFailDemo" name="test3" time="0.001">
    <skipped/>
  </testcase> <!-- test3 -->
  <system-out/>
  <testcase classname="TestNGPractice.RetryFailDemo" name="test3" time="0.002">
    <skipped/>
  </testcase> <!-- test3 -->
  <system-out/>
  <testcase classname="TestNGPractice.RetryFailDemo" name="test2" time="0.002"/>
  <system-out/>
  <testcase classname="TestNGPractice.RetryFailDemo" name="test4" time="0.002"/>
  <system-out/>
  <testcase classname="TestNGPractice.RetryFailDemo" name="test3" time="0.002">
    <error message="/ by zero" type="java.lang.ArithmeticException">
      <![CDATA[java.lang.ArithmeticException: / by zero
at TestNGPractice.RetryFailDemo.test3(RetryFailDemo.java:17)
at java.base/jdk.internal.reflect.NativeMethodAccessorImpl.invoke0(Native Method)
at java.base/jdk.internal.reflect.NativeMethodAccessorImpl.invoke(NativeMethodAccessorImpl.java:77)
at java.base/jdk.internal.reflect.DelegatingMethodAccessorImpl.invoke(DelegatingMethodAccessorImpl.java:43)
at java.base/java.lang.reflect.Method.invoke(Method.java:568)
at org.testng.internal.MethodInvocationHelper.invokeMethod(MethodInvocationHelper.java:133)
at org.testng.internal.TestInvoker.invokeMethod(TestInvoker.java:598)
at org.testng.internal.TestInvoker.retryFailed(TestInvoker.java:213)
at org.testng.internal.MethodRunner.runInSequence(MethodRunner.java:58)
at org.testng.internal.TestInvoker$MethodInvocationAgent.invoke(TestInvoker.java:824)
at org.testng.internal.TestInvoker.invokeTestMethods(TestInvoker.java:146)
at org.testng.internal.TestMethodWorker.invokeTestMethods(TestMethodWorker.java:146)
at org.testng.internal.TestMethodWorker.run(TestMethodWorker.java:128)
at java.base/java.util.ArrayList.forEach(ArrayList.java:1511)
at org.testng.TestRunner.privateRun(TestRunner.java:794)
at org.testng.TestRunner.run(TestRunner.java:596)
at org.testng.SuiteRunner.runTest(SuiteRunner.java:377)
at org.testng.SuiteRunner.runSequentially(SuiteRunner.java:371)
at org.testng.SuiteRunner.privateRun(SuiteRunner.java:332)
at org.testng.SuiteRunner.run(SuiteRunner.java:276)
at org.testng.SuiteRunnerWorker.runSuite(SuiteRunnerWorker.java:53)
at org.testng.SuiteRunnerWorker.run(SuiteRunnerWorker.java:96)
at org.testng.TestNG.runSuitesSequentially(TestNG.java:1212)
at org.testng.TestNG.runSuitesLocally(TestNG.java:1134)
at org.testng.TestNG.runSuites(TestNG.java:1063)
at org.testng.TestNG.run(TestNG.java:1031)
at org.testng.remote.AbstractRemoteTestNG.run(AbstractRemoteTestNG.java:115)
at org.testng.remote.RemoteTestNG.initAndRun(RemoteTestNG.java:251)
at org.testng.remote.RemoteTestNG.main(RemoteTestNG.java:77)
]]>
    </error>
  </testcase> <!-- test3 -->
  <system-out/>
  <testcase classname="TestNGPractice.RetryFailDemo" name="test1" time="0.016"/>
  <system-out/>
  <testcase classname="TestNGPractice.RetryFailDemo" name="test3" time="0.004">
    <skipped/>
  </testcase> <!-- test3 -->
  <system-out/>
  <testcase classname="TestNGPractice.RetryFailDemo" name="test3" time="0.001">
    <skipped/>
  </testcase> <!-- test3 -->
  <system-out/>
</testsuite> <!-- TestNGPractice.RetryFailDemo -->
